[2025-03-21T15:00:01.883+0000] {processor.py:186} INFO - Started process (PID=472) to work on /opt/airflow/dags/dag.py
[2025-03-21T15:00:01.884+0000] {processor.py:914} INFO - Processing file /opt/airflow/dags/dag.py for tasks to queue
[2025-03-21T15:00:01.886+0000] {logging_mixin.py:190} INFO - [2025-03-21T15:00:01.886+0000] {dagbag.py:588} INFO - Filling up the DagBag from /opt/airflow/dags/dag.py
[2025-03-21T15:00:01.911+0000] {logging_mixin.py:190} INFO - [2025-03-21T15:00:01.910+0000] {templater.py:94} ERROR - Failed to resolve template field 'bash_command'
Traceback (most recent call last):
  File "/home/airflow/.local/lib/python3.12/site-packages/airflow/template/templater.py", line 92, in resolve_template_files
    setattr(self, field, env.loader.get_source(env, content)[0])  # type: ignore
                         ^^^^^^^^^^^^^^^^^^^^^^^^^^^^^^^^^^^
  File "/home/airflow/.local/lib/python3.12/site-packages/jinja2/loaders.py", line 209, in get_source
    raise TemplateNotFound(
jinja2.exceptions.TemplateNotFound: 'bash /jobs/CorrigeAge_run.sh' not found in search path: '/opt/airflow/dags'
[2025-03-21T15:00:01.919+0000] {processor.py:925} INFO - DAG(s) 'talend_corrigeage' retrieved from /opt/airflow/dags/dag.py
[2025-03-21T15:00:01.949+0000] {logging_mixin.py:190} INFO - [2025-03-21T15:00:01.948+0000] {dag.py:3239} INFO - Sync 1 DAGs
[2025-03-21T15:00:01.966+0000] {logging_mixin.py:190} INFO - [2025-03-21T15:00:01.966+0000] {dag.py:4180} INFO - Setting next_dagrun for talend_corrigeage to None, run_after=None
[2025-03-21T15:00:01.990+0000] {processor.py:208} INFO - Processing /opt/airflow/dags/dag.py took 0.122 seconds
[2025-03-21T15:00:32.253+0000] {processor.py:186} INFO - Started process (PID=477) to work on /opt/airflow/dags/dag.py
[2025-03-21T15:00:32.255+0000] {processor.py:914} INFO - Processing file /opt/airflow/dags/dag.py for tasks to queue
[2025-03-21T15:00:32.256+0000] {logging_mixin.py:190} INFO - [2025-03-21T15:00:32.256+0000] {dagbag.py:588} INFO - Filling up the DagBag from /opt/airflow/dags/dag.py
[2025-03-21T15:00:32.288+0000] {logging_mixin.py:190} INFO - [2025-03-21T15:00:32.287+0000] {templater.py:94} ERROR - Failed to resolve template field 'bash_command'
Traceback (most recent call last):
  File "/home/airflow/.local/lib/python3.12/site-packages/airflow/template/templater.py", line 92, in resolve_template_files
    setattr(self, field, env.loader.get_source(env, content)[0])  # type: ignore
                         ^^^^^^^^^^^^^^^^^^^^^^^^^^^^^^^^^^^
  File "/home/airflow/.local/lib/python3.12/site-packages/jinja2/loaders.py", line 209, in get_source
    raise TemplateNotFound(
jinja2.exceptions.TemplateNotFound: 'bash /jobs/CorrigeAge_run.sh' not found in search path: '/opt/airflow/dags'
[2025-03-21T15:00:32.293+0000] {processor.py:925} INFO - DAG(s) 'talend_corrigeage' retrieved from /opt/airflow/dags/dag.py
[2025-03-21T15:00:32.323+0000] {logging_mixin.py:190} INFO - [2025-03-21T15:00:32.323+0000] {dag.py:3239} INFO - Sync 1 DAGs
[2025-03-21T15:00:32.343+0000] {logging_mixin.py:190} INFO - [2025-03-21T15:00:32.343+0000] {dag.py:4180} INFO - Setting next_dagrun for talend_corrigeage to None, run_after=None
[2025-03-21T15:00:32.370+0000] {processor.py:208} INFO - Processing /opt/airflow/dags/dag.py took 0.126 seconds
[2025-03-21T15:01:02.775+0000] {processor.py:186} INFO - Started process (PID=482) to work on /opt/airflow/dags/dag.py
[2025-03-21T15:01:02.777+0000] {processor.py:914} INFO - Processing file /opt/airflow/dags/dag.py for tasks to queue
[2025-03-21T15:01:02.779+0000] {logging_mixin.py:190} INFO - [2025-03-21T15:01:02.779+0000] {dagbag.py:588} INFO - Filling up the DagBag from /opt/airflow/dags/dag.py
[2025-03-21T15:01:02.810+0000] {logging_mixin.py:190} INFO - [2025-03-21T15:01:02.809+0000] {templater.py:94} ERROR - Failed to resolve template field 'bash_command'
Traceback (most recent call last):
  File "/home/airflow/.local/lib/python3.12/site-packages/airflow/template/templater.py", line 92, in resolve_template_files
    setattr(self, field, env.loader.get_source(env, content)[0])  # type: ignore
                         ^^^^^^^^^^^^^^^^^^^^^^^^^^^^^^^^^^^
  File "/home/airflow/.local/lib/python3.12/site-packages/jinja2/loaders.py", line 209, in get_source
    raise TemplateNotFound(
jinja2.exceptions.TemplateNotFound: 'bash /jobs/CorrigeAge_run.sh' not found in search path: '/opt/airflow/dags'
[2025-03-21T15:01:02.814+0000] {processor.py:925} INFO - DAG(s) 'talend_corrigeage' retrieved from /opt/airflow/dags/dag.py
[2025-03-21T15:01:02.846+0000] {logging_mixin.py:190} INFO - [2025-03-21T15:01:02.845+0000] {dag.py:3239} INFO - Sync 1 DAGs
[2025-03-21T15:01:02.865+0000] {logging_mixin.py:190} INFO - [2025-03-21T15:01:02.865+0000] {dag.py:4180} INFO - Setting next_dagrun for talend_corrigeage to None, run_after=None
[2025-03-21T15:01:02.891+0000] {processor.py:208} INFO - Processing /opt/airflow/dags/dag.py took 0.128 seconds
[2025-03-21T15:01:03.969+0000] {processor.py:186} INFO - Started process (PID=487) to work on /opt/airflow/dags/dag.py
[2025-03-21T15:01:03.970+0000] {processor.py:914} INFO - Processing file /opt/airflow/dags/dag.py for tasks to queue
[2025-03-21T15:01:03.972+0000] {logging_mixin.py:190} INFO - [2025-03-21T15:01:03.972+0000] {dagbag.py:588} INFO - Filling up the DagBag from /opt/airflow/dags/dag.py
[2025-03-21T15:01:04.027+0000] {logging_mixin.py:190} INFO - [2025-03-21T15:01:04.018+0000] {dagbag.py:387} ERROR - Failed to import: /opt/airflow/dags/dag.py
Traceback (most recent call last):
  File "/home/airflow/.local/lib/python3.12/site-packages/airflow/models/dagbag.py", line 383, in parse
    loader.exec_module(new_module)
  File "<frozen importlib._bootstrap_external>", line 999, in exec_module
  File "<frozen importlib._bootstrap>", line 488, in _call_with_frames_removed
  File "/opt/airflow/dags/dag.py", line 11, in <module>
    run_talend_job = DockerOperator(
                     ^^^^^^^^^^^^^^^
  File "/home/airflow/.local/lib/python3.12/site-packages/airflow/models/baseoperator.py", line 508, in apply_defaults
    result = func(self, **kwargs, default_args=default_args)
             ^^^^^^^^^^^^^^^^^^^^^^^^^^^^^^^^^^^^^^^^^^^^^^^
  File "/home/airflow/.local/lib/python3.12/site-packages/airflow/providers/docker/operators/docker.py", line 256, in __init__
    super().__init__(**kwargs)
  File "/home/airflow/.local/lib/python3.12/site-packages/airflow/models/baseoperator.py", line 508, in apply_defaults
    result = func(self, **kwargs, default_args=default_args)
             ^^^^^^^^^^^^^^^^^^^^^^^^^^^^^^^^^^^^^^^^^^^^^^^
  File "/home/airflow/.local/lib/python3.12/site-packages/airflow/models/baseoperator.py", line 959, in __init__
    raise AirflowException(
airflow.exceptions.AirflowException: Invalid arguments were passed to DockerOperator (task_id: run_talend_corrigeage). Invalid arguments were:
**kwargs: {'volumes': ['/var/run/docker.sock:/var/run/docker.sock']}
[2025-03-21T15:01:04.028+0000] {processor.py:927} WARNING - No viable dags retrieved from /opt/airflow/dags/dag.py
[2025-03-21T15:01:04.053+0000] {processor.py:208} INFO - Processing /opt/airflow/dags/dag.py took 0.090 seconds
[2025-03-21T15:01:05.084+0000] {processor.py:186} INFO - Started process (PID=492) to work on /opt/airflow/dags/dag.py
[2025-03-21T15:01:05.086+0000] {processor.py:914} INFO - Processing file /opt/airflow/dags/dag.py for tasks to queue
[2025-03-21T15:01:05.088+0000] {logging_mixin.py:190} INFO - [2025-03-21T15:01:05.087+0000] {dagbag.py:588} INFO - Filling up the DagBag from /opt/airflow/dags/dag.py
[2025-03-21T15:01:05.136+0000] {logging_mixin.py:190} INFO - [2025-03-21T15:01:05.129+0000] {dagbag.py:387} ERROR - Failed to import: /opt/airflow/dags/dag.py
Traceback (most recent call last):
  File "/home/airflow/.local/lib/python3.12/site-packages/airflow/models/dagbag.py", line 383, in parse
    loader.exec_module(new_module)
  File "<frozen importlib._bootstrap_external>", line 999, in exec_module
  File "<frozen importlib._bootstrap>", line 488, in _call_with_frames_removed
  File "/opt/airflow/dags/dag.py", line 11, in <module>
    run_talend_job = DockerOperator(
                     ^^^^^^^^^^^^^^^
  File "/home/airflow/.local/lib/python3.12/site-packages/airflow/models/baseoperator.py", line 508, in apply_defaults
    result = func(self, **kwargs, default_args=default_args)
             ^^^^^^^^^^^^^^^^^^^^^^^^^^^^^^^^^^^^^^^^^^^^^^^
  File "/home/airflow/.local/lib/python3.12/site-packages/airflow/providers/docker/operators/docker.py", line 256, in __init__
    super().__init__(**kwargs)
  File "/home/airflow/.local/lib/python3.12/site-packages/airflow/models/baseoperator.py", line 508, in apply_defaults
    result = func(self, **kwargs, default_args=default_args)
             ^^^^^^^^^^^^^^^^^^^^^^^^^^^^^^^^^^^^^^^^^^^^^^^
  File "/home/airflow/.local/lib/python3.12/site-packages/airflow/models/baseoperator.py", line 959, in __init__
    raise AirflowException(
airflow.exceptions.AirflowException: Invalid arguments were passed to DockerOperator (task_id: run_talend_corrigeage). Invalid arguments were:
**kwargs: {'volumes': ['/var/run/docker.sock:/var/run/docker.sock']}
[2025-03-21T15:01:05.137+0000] {processor.py:927} WARNING - No viable dags retrieved from /opt/airflow/dags/dag.py
[2025-03-21T15:01:05.161+0000] {processor.py:208} INFO - Processing /opt/airflow/dags/dag.py took 0.085 seconds
[2025-03-21T15:01:35.533+0000] {processor.py:186} INFO - Started process (PID=497) to work on /opt/airflow/dags/dag.py
[2025-03-21T15:01:35.535+0000] {processor.py:914} INFO - Processing file /opt/airflow/dags/dag.py for tasks to queue
[2025-03-21T15:01:35.537+0000] {logging_mixin.py:190} INFO - [2025-03-21T15:01:35.536+0000] {dagbag.py:588} INFO - Filling up the DagBag from /opt/airflow/dags/dag.py
[2025-03-21T15:01:35.566+0000] {logging_mixin.py:190} INFO - [2025-03-21T15:01:35.558+0000] {dagbag.py:387} ERROR - Failed to import: /opt/airflow/dags/dag.py
Traceback (most recent call last):
  File "/home/airflow/.local/lib/python3.12/site-packages/airflow/models/dagbag.py", line 383, in parse
    loader.exec_module(new_module)
  File "<frozen importlib._bootstrap_external>", line 999, in exec_module
  File "<frozen importlib._bootstrap>", line 488, in _call_with_frames_removed
  File "/opt/airflow/dags/dag.py", line 11, in <module>
    run_talend_job = DockerOperator(
                     ^^^^^^^^^^^^^^^
  File "/home/airflow/.local/lib/python3.12/site-packages/airflow/models/baseoperator.py", line 508, in apply_defaults
    result = func(self, **kwargs, default_args=default_args)
             ^^^^^^^^^^^^^^^^^^^^^^^^^^^^^^^^^^^^^^^^^^^^^^^
  File "/home/airflow/.local/lib/python3.12/site-packages/airflow/providers/docker/operators/docker.py", line 256, in __init__
    super().__init__(**kwargs)
  File "/home/airflow/.local/lib/python3.12/site-packages/airflow/models/baseoperator.py", line 508, in apply_defaults
    result = func(self, **kwargs, default_args=default_args)
             ^^^^^^^^^^^^^^^^^^^^^^^^^^^^^^^^^^^^^^^^^^^^^^^
  File "/home/airflow/.local/lib/python3.12/site-packages/airflow/models/baseoperator.py", line 959, in __init__
    raise AirflowException(
airflow.exceptions.AirflowException: Invalid arguments were passed to DockerOperator (task_id: run_talend_corrigeage). Invalid arguments were:
**kwargs: {'volumes': ['/var/run/docker.sock:/var/run/docker.sock']}
[2025-03-21T15:01:35.567+0000] {processor.py:927} WARNING - No viable dags retrieved from /opt/airflow/dags/dag.py
[2025-03-21T15:01:35.591+0000] {processor.py:208} INFO - Processing /opt/airflow/dags/dag.py took 0.067 seconds
[2025-03-21T15:02:05.958+0000] {processor.py:186} INFO - Started process (PID=502) to work on /opt/airflow/dags/dag.py
[2025-03-21T15:02:05.960+0000] {processor.py:914} INFO - Processing file /opt/airflow/dags/dag.py for tasks to queue
[2025-03-21T15:02:05.962+0000] {logging_mixin.py:190} INFO - [2025-03-21T15:02:05.961+0000] {dagbag.py:588} INFO - Filling up the DagBag from /opt/airflow/dags/dag.py
[2025-03-21T15:02:05.983+0000] {logging_mixin.py:190} INFO - [2025-03-21T15:02:05.978+0000] {dagbag.py:387} ERROR - Failed to import: /opt/airflow/dags/dag.py
Traceback (most recent call last):
  File "/home/airflow/.local/lib/python3.12/site-packages/airflow/models/dagbag.py", line 383, in parse
    loader.exec_module(new_module)
  File "<frozen importlib._bootstrap_external>", line 999, in exec_module
  File "<frozen importlib._bootstrap>", line 488, in _call_with_frames_removed
  File "/opt/airflow/dags/dag.py", line 11, in <module>
    run_talend_job = DockerOperator(
                     ^^^^^^^^^^^^^^^
  File "/home/airflow/.local/lib/python3.12/site-packages/airflow/models/baseoperator.py", line 508, in apply_defaults
    result = func(self, **kwargs, default_args=default_args)
             ^^^^^^^^^^^^^^^^^^^^^^^^^^^^^^^^^^^^^^^^^^^^^^^
  File "/home/airflow/.local/lib/python3.12/site-packages/airflow/providers/docker/operators/docker.py", line 256, in __init__
    super().__init__(**kwargs)
  File "/home/airflow/.local/lib/python3.12/site-packages/airflow/models/baseoperator.py", line 508, in apply_defaults
    result = func(self, **kwargs, default_args=default_args)
             ^^^^^^^^^^^^^^^^^^^^^^^^^^^^^^^^^^^^^^^^^^^^^^^
  File "/home/airflow/.local/lib/python3.12/site-packages/airflow/models/baseoperator.py", line 959, in __init__
    raise AirflowException(
airflow.exceptions.AirflowException: Invalid arguments were passed to DockerOperator (task_id: run_talend_corrigeage). Invalid arguments were:
**kwargs: {'volumes': ['/var/run/docker.sock:/var/run/docker.sock']}
[2025-03-21T15:02:05.984+0000] {processor.py:927} WARNING - No viable dags retrieved from /opt/airflow/dags/dag.py
[2025-03-21T15:02:06.008+0000] {processor.py:208} INFO - Processing /opt/airflow/dags/dag.py took 0.057 seconds
[2025-03-21T15:02:36.355+0000] {processor.py:186} INFO - Started process (PID=507) to work on /opt/airflow/dags/dag.py
[2025-03-21T15:02:36.357+0000] {processor.py:914} INFO - Processing file /opt/airflow/dags/dag.py for tasks to queue
[2025-03-21T15:02:36.359+0000] {logging_mixin.py:190} INFO - [2025-03-21T15:02:36.358+0000] {dagbag.py:588} INFO - Filling up the DagBag from /opt/airflow/dags/dag.py
[2025-03-21T15:02:36.385+0000] {logging_mixin.py:190} INFO - [2025-03-21T15:02:36.377+0000] {dagbag.py:387} ERROR - Failed to import: /opt/airflow/dags/dag.py
Traceback (most recent call last):
  File "/home/airflow/.local/lib/python3.12/site-packages/airflow/models/dagbag.py", line 383, in parse
    loader.exec_module(new_module)
  File "<frozen importlib._bootstrap_external>", line 999, in exec_module
  File "<frozen importlib._bootstrap>", line 488, in _call_with_frames_removed
  File "/opt/airflow/dags/dag.py", line 11, in <module>
    run_talend_job = DockerOperator(
                     ^^^^^^^^^^^^^^^
  File "/home/airflow/.local/lib/python3.12/site-packages/airflow/models/baseoperator.py", line 508, in apply_defaults
    result = func(self, **kwargs, default_args=default_args)
             ^^^^^^^^^^^^^^^^^^^^^^^^^^^^^^^^^^^^^^^^^^^^^^^
  File "/home/airflow/.local/lib/python3.12/site-packages/airflow/providers/docker/operators/docker.py", line 256, in __init__
    super().__init__(**kwargs)
  File "/home/airflow/.local/lib/python3.12/site-packages/airflow/models/baseoperator.py", line 508, in apply_defaults
    result = func(self, **kwargs, default_args=default_args)
             ^^^^^^^^^^^^^^^^^^^^^^^^^^^^^^^^^^^^^^^^^^^^^^^
  File "/home/airflow/.local/lib/python3.12/site-packages/airflow/models/baseoperator.py", line 959, in __init__
    raise AirflowException(
airflow.exceptions.AirflowException: Invalid arguments were passed to DockerOperator (task_id: run_talend_corrigeage). Invalid arguments were:
**kwargs: {'volumes': ['/var/run/docker.sock:/var/run/docker.sock']}
[2025-03-21T15:02:36.387+0000] {processor.py:927} WARNING - No viable dags retrieved from /opt/airflow/dags/dag.py
[2025-03-21T15:02:36.413+0000] {processor.py:208} INFO - Processing /opt/airflow/dags/dag.py took 0.069 seconds
[2025-03-21T15:03:06.754+0000] {processor.py:186} INFO - Started process (PID=512) to work on /opt/airflow/dags/dag.py
[2025-03-21T15:03:06.758+0000] {processor.py:914} INFO - Processing file /opt/airflow/dags/dag.py for tasks to queue
[2025-03-21T15:03:06.766+0000] {logging_mixin.py:190} INFO - [2025-03-21T15:03:06.765+0000] {dagbag.py:588} INFO - Filling up the DagBag from /opt/airflow/dags/dag.py
[2025-03-21T15:03:06.812+0000] {logging_mixin.py:190} INFO - [2025-03-21T15:03:06.798+0000] {dagbag.py:387} ERROR - Failed to import: /opt/airflow/dags/dag.py
Traceback (most recent call last):
  File "/home/airflow/.local/lib/python3.12/site-packages/airflow/models/dagbag.py", line 383, in parse
    loader.exec_module(new_module)
  File "<frozen importlib._bootstrap_external>", line 999, in exec_module
  File "<frozen importlib._bootstrap>", line 488, in _call_with_frames_removed
  File "/opt/airflow/dags/dag.py", line 11, in <module>
    run_talend_job = DockerOperator(
                     ^^^^^^^^^^^^^^^
  File "/home/airflow/.local/lib/python3.12/site-packages/airflow/models/baseoperator.py", line 508, in apply_defaults
    result = func(self, **kwargs, default_args=default_args)
             ^^^^^^^^^^^^^^^^^^^^^^^^^^^^^^^^^^^^^^^^^^^^^^^
  File "/home/airflow/.local/lib/python3.12/site-packages/airflow/providers/docker/operators/docker.py", line 256, in __init__
    super().__init__(**kwargs)
  File "/home/airflow/.local/lib/python3.12/site-packages/airflow/models/baseoperator.py", line 508, in apply_defaults
    result = func(self, **kwargs, default_args=default_args)
             ^^^^^^^^^^^^^^^^^^^^^^^^^^^^^^^^^^^^^^^^^^^^^^^
  File "/home/airflow/.local/lib/python3.12/site-packages/airflow/models/baseoperator.py", line 959, in __init__
    raise AirflowException(
airflow.exceptions.AirflowException: Invalid arguments were passed to DockerOperator (task_id: run_talend_corrigeage). Invalid arguments were:
**kwargs: {'volumes': ['/var/run/docker.sock:/var/run/docker.sock']}
[2025-03-21T15:03:06.823+0000] {processor.py:927} WARNING - No viable dags retrieved from /opt/airflow/dags/dag.py
[2025-03-21T15:03:06.896+0000] {processor.py:208} INFO - Processing /opt/airflow/dags/dag.py took 0.178 seconds
[2025-03-21T15:03:37.795+0000] {processor.py:186} INFO - Started process (PID=517) to work on /opt/airflow/dags/dag.py
[2025-03-21T15:03:37.829+0000] {processor.py:914} INFO - Processing file /opt/airflow/dags/dag.py for tasks to queue
[2025-03-21T15:03:37.839+0000] {logging_mixin.py:190} INFO - [2025-03-21T15:03:37.837+0000] {dagbag.py:588} INFO - Filling up the DagBag from /opt/airflow/dags/dag.py
[2025-03-21T15:03:37.900+0000] {logging_mixin.py:190} INFO - [2025-03-21T15:03:37.884+0000] {dagbag.py:387} ERROR - Failed to import: /opt/airflow/dags/dag.py
Traceback (most recent call last):
  File "/home/airflow/.local/lib/python3.12/site-packages/airflow/models/dagbag.py", line 383, in parse
    loader.exec_module(new_module)
  File "<frozen importlib._bootstrap_external>", line 999, in exec_module
  File "<frozen importlib._bootstrap>", line 488, in _call_with_frames_removed
  File "/opt/airflow/dags/dag.py", line 11, in <module>
    run_talend_job = DockerOperator(
                     ^^^^^^^^^^^^^^^
  File "/home/airflow/.local/lib/python3.12/site-packages/airflow/models/baseoperator.py", line 508, in apply_defaults
    result = func(self, **kwargs, default_args=default_args)
             ^^^^^^^^^^^^^^^^^^^^^^^^^^^^^^^^^^^^^^^^^^^^^^^
  File "/home/airflow/.local/lib/python3.12/site-packages/airflow/providers/docker/operators/docker.py", line 256, in __init__
    super().__init__(**kwargs)
  File "/home/airflow/.local/lib/python3.12/site-packages/airflow/models/baseoperator.py", line 508, in apply_defaults
    result = func(self, **kwargs, default_args=default_args)
             ^^^^^^^^^^^^^^^^^^^^^^^^^^^^^^^^^^^^^^^^^^^^^^^
  File "/home/airflow/.local/lib/python3.12/site-packages/airflow/models/baseoperator.py", line 959, in __init__
    raise AirflowException(
airflow.exceptions.AirflowException: Invalid arguments were passed to DockerOperator (task_id: run_talend_corrigeage). Invalid arguments were:
**kwargs: {'volumes': ['/var/run/docker.sock:/var/run/docker.sock']}
[2025-03-21T15:03:37.909+0000] {processor.py:927} WARNING - No viable dags retrieved from /opt/airflow/dags/dag.py
[2025-03-21T15:03:37.994+0000] {processor.py:208} INFO - Processing /opt/airflow/dags/dag.py took 0.347 seconds
