[2025-04-04T13:12:17.431+0000] {local_task_job_runner.py:123} INFO - ::group::Pre task execution logs
[2025-04-04T13:12:17.466+0000] {taskinstance.py:2614} INFO - Dependencies all met for dep_context=non-requeueable deps ti=<TaskInstance: talend_direct_execution.execute_talend_job manual__2025-04-04T13:12:15.385914+00:00 [queued]>
[2025-04-04T13:12:17.481+0000] {taskinstance.py:2614} INFO - Dependencies all met for dep_context=requeueable deps ti=<TaskInstance: talend_direct_execution.execute_talend_job manual__2025-04-04T13:12:15.385914+00:00 [queued]>
[2025-04-04T13:12:17.483+0000] {taskinstance.py:2867} INFO - Starting attempt 1 of 1
[2025-04-04T13:12:17.507+0000] {taskinstance.py:2890} INFO - Executing <Task(BashOperator): execute_talend_job> on 2025-04-04 13:12:15.385914+00:00
[2025-04-04T13:12:17.524+0000] {logging_mixin.py:190} WARNING - /home/***/.local/lib/python3.12/site-packages/***/task/task_runner/standard_task_runner.py:70 DeprecationWarning: This process (pid=218) is multi-threaded, use of fork() may lead to deadlocks in the child.
[2025-04-04T13:12:17.526+0000] {standard_task_runner.py:72} INFO - Started process 219 to run task
[2025-04-04T13:12:17.525+0000] {standard_task_runner.py:104} INFO - Running: ['***', 'tasks', 'run', 'talend_direct_execution', 'execute_talend_job', 'manual__2025-04-04T13:12:15.385914+00:00', '--job-id', '474', '--raw', '--subdir', 'DAGS_FOLDER/test.py', '--cfg-path', '/tmp/tmpj8d94jkt']
[2025-04-04T13:12:17.528+0000] {standard_task_runner.py:105} INFO - Job 474: Subtask execute_talend_job
[2025-04-04T13:12:17.552+0000] {logging_mixin.py:190} WARNING - /home/***/.local/lib/python3.12/site-packages/***/settings.py:209 DeprecationWarning: The sql_alchemy_conn option in [core] has been moved to the sql_alchemy_conn option in [database] - the old setting has been used, but please update your config.
[2025-04-04T13:12:17.596+0000] {task_command.py:467} INFO - Running <TaskInstance: talend_direct_execution.execute_talend_job manual__2025-04-04T13:12:15.385914+00:00 [running]> on host 98a2ddb84e26
[2025-04-04T13:12:17.720+0000] {taskinstance.py:3134} INFO - Exporting env vars: AIRFLOW_CTX_DAG_OWNER='***' AIRFLOW_CTX_DAG_ID='talend_direct_execution' AIRFLOW_CTX_TASK_ID='execute_talend_job' AIRFLOW_CTX_EXECUTION_DATE='2025-04-04T13:12:15.385914+00:00' AIRFLOW_CTX_TRY_NUMBER='1' AIRFLOW_CTX_DAG_RUN_ID='manual__2025-04-04T13:12:15.385914+00:00'
[2025-04-04T13:12:17.722+0000] {taskinstance.py:732} INFO - ::endgroup::
[2025-04-04T13:12:17.747+0000] {subprocess.py:78} INFO - Tmp dir root location: /tmp
[2025-04-04T13:12:17.748+0000] {subprocess.py:88} INFO - Running command: ['/usr/bin/bash', '-c', '\n        cd /opt/***/talend_jobs/CorrigeAge/CorrigeAge && \n        chmod +x ./CorrigeAge_run.sh && \n        ./CorrigeAge_run.sh > /opt/***/talend_jobs/CorrigeAge/job_output.log 2>&1\n        ']
[2025-04-04T13:12:17.762+0000] {subprocess.py:99} INFO - Output:
[2025-04-04T13:12:17.776+0000] {subprocess.py:106} INFO - chmod: changing permissions of './CorrigeAge_run.sh': Operation not permitted
[2025-04-04T13:12:17.777+0000] {subprocess.py:110} INFO - Command exited with return code 1
[2025-04-04T13:12:17.790+0000] {taskinstance.py:3313} ERROR - Task failed with exception
Traceback (most recent call last):
  File "/home/airflow/.local/lib/python3.12/site-packages/airflow/models/taskinstance.py", line 768, in _execute_task
    result = _execute_callable(context=context, **execute_callable_kwargs)
             ^^^^^^^^^^^^^^^^^^^^^^^^^^^^^^^^^^^^^^^^^^^^^^^^^^^^^^^^^^^^^
  File "/home/airflow/.local/lib/python3.12/site-packages/airflow/models/taskinstance.py", line 734, in _execute_callable
    return ExecutionCallableRunner(
           ^^^^^^^^^^^^^^^^^^^^^^^^
  File "/home/airflow/.local/lib/python3.12/site-packages/airflow/utils/operator_helpers.py", line 252, in run
    return self.func(*args, **kwargs)
           ^^^^^^^^^^^^^^^^^^^^^^^^^^
  File "/home/airflow/.local/lib/python3.12/site-packages/airflow/models/baseoperator.py", line 424, in wrapper
    return func(self, *args, **kwargs)
           ^^^^^^^^^^^^^^^^^^^^^^^^^^^
  File "/home/airflow/.local/lib/python3.12/site-packages/airflow/operators/bash.py", line 276, in execute
    raise AirflowException(
airflow.exceptions.AirflowException: Bash command failed. The command returned a non-zero exit code 1.
[2025-04-04T13:12:17.796+0000] {taskinstance.py:1226} INFO - Marking task as FAILED. dag_id=talend_direct_execution, task_id=execute_talend_job, run_id=manual__2025-04-04T13:12:15.385914+00:00, execution_date=20250404T131215, start_date=20250404T131217, end_date=20250404T131217
[2025-04-04T13:12:17.835+0000] {taskinstance.py:341} INFO - ::group::Post task execution logs
[2025-04-04T13:12:17.838+0000] {standard_task_runner.py:124} ERROR - Failed to execute job 474 for task execute_talend_job (Bash command failed. The command returned a non-zero exit code 1.; 219)
Traceback (most recent call last):
  File "/home/airflow/.local/lib/python3.12/site-packages/airflow/task/task_runner/standard_task_runner.py", line 117, in _start_by_fork
    ret = args.func(args, dag=self.dag)
          ^^^^^^^^^^^^^^^^^^^^^^^^^^^^^
  File "/home/airflow/.local/lib/python3.12/site-packages/airflow/cli/cli_config.py", line 49, in command
    return func(*args, **kwargs)
           ^^^^^^^^^^^^^^^^^^^^^
  File "/home/airflow/.local/lib/python3.12/site-packages/airflow/utils/cli.py", line 116, in wrapper
    return f(*args, **kwargs)
           ^^^^^^^^^^^^^^^^^^
  File "/home/airflow/.local/lib/python3.12/site-packages/airflow/cli/commands/task_command.py", line 483, in task_run
    task_return_code = _run_task_by_selected_method(args, _dag, ti)
                       ^^^^^^^^^^^^^^^^^^^^^^^^^^^^^^^^^^^^^^^^^^^^
  File "/home/airflow/.local/lib/python3.12/site-packages/airflow/cli/commands/task_command.py", line 256, in _run_task_by_selected_method
    return _run_raw_task(args, ti)
           ^^^^^^^^^^^^^^^^^^^^^^^
  File "/home/airflow/.local/lib/python3.12/site-packages/airflow/cli/commands/task_command.py", line 341, in _run_raw_task
    return ti._run_raw_task(
           ^^^^^^^^^^^^^^^^^
  File "/home/airflow/.local/lib/python3.12/site-packages/airflow/utils/session.py", line 97, in wrapper
    return func(*args, session=session, **kwargs)
           ^^^^^^^^^^^^^^^^^^^^^^^^^^^^^^^^^^^^^^
  File "/home/airflow/.local/lib/python3.12/site-packages/airflow/models/taskinstance.py", line 3006, in _run_raw_task
    return _run_raw_task(
           ^^^^^^^^^^^^^^
  File "/home/airflow/.local/lib/python3.12/site-packages/airflow/models/taskinstance.py", line 274, in _run_raw_task
    TaskInstance._execute_task_with_callbacks(
  File "/home/airflow/.local/lib/python3.12/site-packages/airflow/models/taskinstance.py", line 3161, in _execute_task_with_callbacks
    result = self._execute_task(context, task_orig)
             ^^^^^^^^^^^^^^^^^^^^^^^^^^^^^^^^^^^^^^
  File "/home/airflow/.local/lib/python3.12/site-packages/airflow/models/taskinstance.py", line 3185, in _execute_task
    return _execute_task(self, context, task_orig)
           ^^^^^^^^^^^^^^^^^^^^^^^^^^^^^^^^^^^^^^^
  File "/home/airflow/.local/lib/python3.12/site-packages/airflow/models/taskinstance.py", line 768, in _execute_task
    result = _execute_callable(context=context, **execute_callable_kwargs)
             ^^^^^^^^^^^^^^^^^^^^^^^^^^^^^^^^^^^^^^^^^^^^^^^^^^^^^^^^^^^^^
  File "/home/airflow/.local/lib/python3.12/site-packages/airflow/models/taskinstance.py", line 734, in _execute_callable
    return ExecutionCallableRunner(
           ^^^^^^^^^^^^^^^^^^^^^^^^
  File "/home/airflow/.local/lib/python3.12/site-packages/airflow/utils/operator_helpers.py", line 252, in run
    return self.func(*args, **kwargs)
           ^^^^^^^^^^^^^^^^^^^^^^^^^^
  File "/home/airflow/.local/lib/python3.12/site-packages/airflow/models/baseoperator.py", line 424, in wrapper
    return func(self, *args, **kwargs)
           ^^^^^^^^^^^^^^^^^^^^^^^^^^^
  File "/home/airflow/.local/lib/python3.12/site-packages/airflow/operators/bash.py", line 276, in execute
    raise AirflowException(
airflow.exceptions.AirflowException: Bash command failed. The command returned a non-zero exit code 1.
[2025-04-04T13:12:17.864+0000] {local_task_job_runner.py:266} INFO - Task exited with return code 1
[2025-04-04T13:12:17.886+0000] {taskinstance.py:3901} INFO - 0 downstream tasks scheduled from follow-on schedule check
[2025-04-04T13:12:17.893+0000] {local_task_job_runner.py:245} INFO - ::endgroup::
